<?xml version="1.0"?>
<robot name="ackerman_drive_robot">

    <link name="base_link">
        <inertial>
            <mass value="1.0"/>
            <inertia ixx="0.01" ixy="0.0" ixz="0.0" iyy="0.01" iyz="0.0" izz="0.01"/>
        </inertial>
        <visual>
            <geometry>
                <box size="1.0 1.0 0.05"/>
            </geometry>
            <material name="white">
                <color rgba="1.0 1.0 1.0 1.0"/>
            </material>
        </visual>
        <collision>
            <geometry>
                <box size="1.0 1.0 0.05"/>
            </geometry>
        </collision>
    </link>

    
    <joint name="dock_joint" type="continuous">
        <origin xyz="0.0 0.0 0.05" rpy="0.0 0.0 0.0"/>
        <parent link="base_link"/>
        <child link="dock_link"/>
        <axis xyz="0.0 0.0 1"/>
    </joint>
    <link name="dock_link">
        <inertial>
            <mass value="1.0"/>
            <inertia ixx="0.01" ixy="0.0" ixz="0.0" iyy="0.01" iyz="0.0" izz="0.01"/>
        </inertial>
        <visual>
            <geometry>
                <cylinder radius="0.1875" length="0.05"/>
            </geometry>
            <material name="white">
                <color rgba="1.0 1.0 1.0 1.0"/>
            </material>
        </visual>
        <collision>
            <geometry>
                <cylinder radius="0.1875" length="0.05"/>
            </geometry>
        </collision>
    </link>


    <joint name="stick1_joint" type="revolute">
        <origin xyz="0.0 0.0 0.0" rpy="0.0 0.0 0.0"/>
        <parent link="dock_link"/>
        <child link="stick1_link"/>
        <axis xyz="0.0 1 0.0"/>
        <limit lower="-1.57" upper="1.57" effort="100" velocity="100"/>
    </joint>
    <link name="stick1_link">
        <inertial>
            <mass value="1.0"/>
            <inertia ixx="0.01" ixy="0.0" ixz="0.0" iyy="0.01" iyz="0.0" izz="0.01"/>
        </inertial>
        <visual>
            <origin xyz="0.0 0.0 0.2"/>
            <geometry>
                <cylinder radius="0.05" length="0.4"/>
            </geometry>
            <material name="red">
                <color rgba="1.0 0.0 0.0 1.0"/>
            </material>
        </visual>
        <collision>
            <geometry>
                <cylinder radius="0.05" length="0.4"/>
            </geometry>
            <contact_coefficient mu="1" kp="1e+13" kd="1.0"/>
        </collision>
    </link>


    <joint name="stick2_joint" type="revolute">
        <origin xyz="0.0 0.1 0.3" rpy="0.0 0.0 0.0"/>
        <parent link="stick1_link"/>
        <child link="stick2_link"/>
        <axis xyz="0.0 1 0.0"/>
        <limit lower="-1.57" upper="1.57" effort="100" velocity="100"/>
    </joint>
    <link name="stick2_link">
        <inertial>
            <mass value="1.0"/>
            <inertia ixx="0.01" ixy="0.0" ixz="0.0" iyy="0.01" iyz="0.0" izz="0.01"/>
        </inertial>
        <visual>
            <origin xyz="0.0 0.0 0.2"/>
            <geometry>
                <cylinder radius="0.05" length="0.4"/>
            </geometry>
            <material name="green">
                <color rgba="0.0 1.0 0.0 1.0"/>
            </material>
        </visual>
        <collision>
            <geometry>
                <cylinder radius="0.05" length="0.4"/>
            </geometry>
            <contact_coefficient mu="1" kp="1e+13" kd="1.0"/>
        </collision>
    </link>



    <joint name="stick3_joint" type="revolute">
        <origin xyz="0.0 -0.1 0.3" rpy="0.0 0.0 0.0"/>
        <parent link="stick2_link"/>
        <child link="stick3_link"/>
        <axis xyz="0.0 1 0.0"/>
        <limit lower="-1.57" upper="1.57" effort="100" velocity="100"/>
    </joint>
    <link name="stick3_link">
        <inertial>
            <mass value="1.0"/>
            <inertia ixx="0.01" ixy="0.0" ixz="0.0" iyy="0.01" iyz="0.0" izz="0.01"/>
        </inertial>
        <visual>
            <origin xyz="0.0 0.0 0.2"/>
            <geometry>
                <cylinder radius="0.05" length="0.4"/>
            </geometry>
            <material name="blue">
                <color rgba="0.0 0.0 1.0 1.0"/>
            </material>
        </visual>
        <collision>
            <geometry>
                <cylinder radius="0.05" length="0.4"/>
            </geometry>
            <contact_coefficient mu="1" kp="1e+13" kd="1.0"/>
        </collision>
    </link>
</robot>